Workbook
Name UN: #REF!
Name Coeffs_121: #REF!
Name Coeffs_143: #REF!
Name Family: #REF!
Name Coeffs_221: #REF!
Name Coeffs_141: #REF!
Name Coeffs_251: #REF!
Name Coeffs_231: #REF!
Name Princeton: #REF!
Name Coeffs_131: #REF!
Name Coeffs_211: #REF!
Name Coeffs_113: #REF!
Name Variant: #REF!
Name Coeffs_123: #REF!
Name Coeffs_112: #REF!
Name Coeffs_132: #REF!
Name Coeffs_133: #REF!
Name Coeffs_111: #REF!
Name Coeffs_142: #REF!
Name TypeSelect: #REF!
Name Coeffs_122: #REF!
Name Coeffs_241: #REF!
Name Sex: #REF!
Name FamSelect: #REF!

Sheet Decrementos Múltiples
B2: Hombres, 2019
B3: Age x | C3: n | D3: nDx | E3: nDxi | I3: nqx | K3: e0 | M3: nqx_i | O3: ndx_i | Q3: L | R3: T | S3: e0_i | T3: diff
B4: 0 | C4: 1 | D4: 143 | E4: 1 | F4: =(D4-E4)/D4 -> 0.99300699 | G4: =LT!H21 -> 100000 | H4: =1-LT!F21 -> 0.98819741 | I4: =1-H4 -> 0.01180259 | J4: =LT!G2 | K4: =LT!L21 -> 66.515702 | L4: =H4^F4 -> 0.98827946 | M4: =1-L4 -> 0.01172054 | N4: 100000 | O4: =N4*M4 -> 1172.054 | P4: =C4+(F4*(I4/M4)*(J4-C4)) -> 4.1430545e-05 | Q4: =(C4*N5)+(P4*O4) -> 98827.995 | R4: =R5+Q4 -> 6685828.4 | S4: =R4/N4 -> 66.858284 | T4: =S4-K4 -> 0.34258188
B5: 1 | C5: 4 | D5: 23 | E5: 0 | F5: =(D5-E5)/D5 -> 1 | G5: =LT!H22 -> 98819.741 | H5: =1-LT!F22 -> 0.99790482 | I5: =1-H5 -> 0.0020951826 | J5: =LT!G3 | K5: =LT!L22 -> 66.309216 | L5: =H5^F5 -> 0.99790482 | M5: =1-L5 -> 0.0020951826 | N5: =N4*L4 -> 98827.946 | O5: =N5*M5 -> 207.06259 | P5: =C5+(F5*(I5/M5)*(J5-C5)) -> 0 | Q5: =(C5*N6)+(P5*O5) -> 394483.53 | R5: =R6+Q5 -> 6587000.4 | S5: =R5/N5 -> 66.651192 | T5: =S5-K5 -> 0.34197593 | V5: Número de años que se espera que viva un hombre de 0 años hasta llegar a los 85 años.
B6: 5 | C6: 5 | D6: 14 | E6: 3 | F6: =(D6-E6)/D6 -> 0.78571429 | G6: =LT!H23 -> 98612.696 | H6: =1-LT!F23 -> 0.99883072 | I6: =1-H6 -> 0.0011692781 | J6: =LT!G4 | K6: =LT!L23 -> 62.444901 | L6: =H6^F6 -> 0.99908117 | M6: =1-L6 -> 0.00091883362 | N6: =N5*L5 -> 98620.883 | O6: =N6*M6 -> 90.616184 | P6: =C6+(F6*(I6/M6)*(J6-C6)) -> 0.00062661707 | Q6: =(C6*N7)+(P6*O6) -> 492651.39 | R6: =R7+Q6 -> 6192516.9 | S6: =R6/N6 -> 62.791132 | T6: =S6-K6 -> 0.3462309
B7: 10 | C7: 5 | D7: 10 | E7: 0 | F7: =(D7-E7)/D7 -> 1 | G7: =LT!H24 -> 98497.39 | H7: =1-LT!F24 -> 0.99917672 | I7: =1-H7 -> 0.00082327565 | J7: =LT!G5 | K7: =LT!L24 -> 57.515075 | L7: =H7^F7 -> 0.99917672 | M7: =1-L7 -> 0.00082327565 | N7: =N6*L6 -> 98530.267 | O7: =N7*M7 -> 81.11757 | P7: =(((-5/24)*O6)+((2.5)*O7)+((5/24)*O8))/O7 -> 3.2324343 | Q7: =(C7*N8)+(P7*O7) -> 492507.96 | R7: =R8+Q7 -> 5699865.5 | S7: =R7/N7 -> 57.848879 | T7: =S7-K7 -> 0.33380368
B8: 15 | C8: 5 | D8: 56 | E8: 9 | F8: =(D8-E8)/D8 -> 0.83928571 | G8: =LT!H25 -> 98416.299 | H8: =1-LT!F25 -> 0.99545351 | I8: =1-H8 -> 0.0045464878 | J8: =LT!G6 | K8: =LT!L25 -> 52.560405 | L8: =H8^F8 -> 0.9961828 | M8: =1-L8 -> 0.0038171988 | N8: =N7*L7 -> 98449.15 | O8: =N8*M8 -> 375.79998 | P8: =(((-5/24)*O7)+((2.5)*O8)+((5/24)*O9))/O8 -> 2.7913676 | Q8: =(C8*N9)+(P8*O8) -> 491415.74 | R8: =R9+Q8 -> 5207357.5 | S8: =R8/N8 -> 52.89388 | T8: =S8-K8 -> 0.33347522 | V8: Sin COVID | W8: Con COVID
B9: 20 | C9: 5 | D9: 95 | E9: 25 | F9: =(D9-E9)/D9 -> 0.73684211 | G9: =LT!H26 -> 97968.851 | H9: =1-LT!F26 -> 0.99161377 | I9: =1-H9 -> 0.0083862254 | J9: =LT!G7 | K9: =LT!L26 -> 47.789043 | L9: =H9^F9 -> 0.99381383 | M9: =1-L9 -> 0.0061861668 | N9: =N8*L8 -> 98073.35 | O9: =N9*M9 -> 606.6981 | P9: =(((-5/24)*O8)+((2.5)*O9)+((5/24)*O10))/O9 -> 2.7467755 | Q9: =(C9*N10)+(P9*O9) -> 488999.72 | R9: =R10+Q9 -> 4715941.8 | S9: =R9/N9 -> 48.085864 | T9: =S9-K9 -> 0.29682079 | V9: =([1]TV!M53-[1]TV!M71)/[1]TV!J53 -> #ERROR! | W9: =(R4-R22)/N4 -> 66.083837
B10: 25 | C10: 5 | D10: 144 | E10: 30 | F10: =(D10-E10)/D10 -> 0.79166667 | G10: =LT!H27 -> 97147.262 | H10: =1-LT!F27 -> 0.98583709 | I10: =1-H10 -> 0.014162913 | J10: =LT!G8 | K10: =LT!L27 -> 43.17206 | L10: =H10^F10 -> 0.98877106 | M10: =1-L10 -> 0.011228943 | N10: =N9*L9 -> 97466.652 | O10: =N10*M10 -> 1094.4474 | P10: =(((-5/24)*O9)+((2.5)*O10)+((5/24)*O11))/O10 -> 2.6604922 | Q10: =(C10*N11)+(P10*O10) -> 484772.79 | R10: =R11+Q10 -> 4226942.1 | S10: =R10/N10 -> 43.368085 | T10: =S10-K10 -> 0.19602564 | V10: Diff | W10: =W9-V9 -> #ERROR!
B11: 30 | C11: 5 | D11: 157 | E11: 20 | F11: =(D11-E11)/D11 -> 0.87261146 | G11: =LT!H28 -> 95771.374 | H11: =1-LT!F28 -> 0.98277886 | I11: =1-H11 -> 0.017221144 | J11: =LT!G9 | K11: =LT!L28 -> 38.75637 | L11: =H11^F11 -> 0.98495604 | M11: =1-L11 -> 0.015043958 | N11: =N10*L10 -> 96372.204 | O11: =N11*M11 -> 1449.8194 | P11: =(((-5/24)*O10)+((2.5)*O11)+((5/24)*O12))/O11 -> 2.6090647 | Q11: =(C11*N12)+(P11*O11) -> 478394.6 | R11: =R12+Q11 -> 3742169.3 | S11: =R11/N11 -> 38.83038 | T11: =S11-K11 -> 0.074009568
B12: 35 | C12: 5 | D12: 197 | E12: 26 | F12: =(D12-E12)/D12 -> 0.8680203 | G12: =LT!H29 -> 94122.081 | H12: =1-LT!F29 -> 0.97753885 | I12: =1-H12 -> 0.022461149 | J12: =LT!G10 | K12: =LT!L29 -> 34.391687 | L12: =H12^F12 -> 0.98047412 | M12: =1-L12 -> 0.01952588 | N12: =N11*L11 -> 94922.385 | O12: =N12*M12 -> 1853.4431 | P12: =(((-5/24)*O11)+((2.5)*O12)+((5/24)*O13))/O12 -> 2.6826339 | Q12: =(C12*N13)+(P12*O12) -> 470316.82 | R12: =R13+Q12 -> 3263774.7 | S12: =R12/N12 -> 34.383614 | T12: =S12-K12 -> -0.0080726789
B13: 40 | C13: 5 | D13: 290 | E13: 14 | F13: =(D13-E13)/D13 -> 0.95172414 | G13: =LT!H30 -> 92007.991 | H13: =1-LT!F30 -> 0.96531764 | I13: =1-H13 -> 0.034682357 | J13: =LT!G11 | K13: =LT!L30 -> 30.12447 | L13: =H13^F13 -> 0.96696399 | M13: =1-L13 -> 0.033036011 | N13: =N12*L12 -> 93068.942 | O13: =N13*M13 -> 3074.6266 | P13: =(((-5/24)*O12)+((2.5)*O13)+((5/24)*O14))/O13 -> 2.6875038 | Q13: =(C13*N14)+(P13*O13) -> 458234.65 | R13: =R14+Q13 -> 2793457.9 | S13: =R13/N13 -> 30.014931 | T13: =S13-K13 -> -0.10953923
B14: 45 | C14: 5 | D14: 398 | E14: 11 | F14: =(D14-E14)/D14 -> 0.97236181 | G14: =LT!H31 -> 88816.937 | H14: =1-LT!F31 -> 0.94723585 | I14: =1-H14 -> 0.052764152 | J14: =LT!G12 | K14: =LT!L31 -> 26.116974 | L14: =H14^F14 -> 0.94865605 | M14: =1-L14 -> 0.051343951 | N14: =N13*L13 -> 89994.315 | O14: =N14*M14 -> 4620.6637 | P14: =(((-5/24)*O13)+((2.5)*O14)+((5/24)*O15))/O14 -> 2.6481303 | Q14: =(C14*N15)+(P14*O14) -> 439104.38 | R14: =R15+Q14 -> 2335223.2 | S14: =R14/N14 -> 25.948564 | T14: =S14-K14 -> -0.16841069
B15: 50 | C15: 5 | D15: 502 | E15: 7 | F15: =(D15-E15)/D15 -> 0.98605578 | G15: =LT!H32 -> 84130.587 | H15: =1-LT!F32 -> 0.92449084 | I15: =1-H15 -> 0.07550916 | J15: =LT!G13 | K15: =LT!L32 -> 22.432517 | L15: =H15^F15 -> 0.92550352 | M15: =1-L15 -> 0.074496482 | N15: =N14*L14 -> 85373.651 | O15: =N15*M15 -> 6360.0367 | P15: =(((-5/24)*O14)+((2.5)*O15)+((5/24)*O16))/O15 -> 2.6130079 | Q15: =(C15*N16)+(P15*O15) -> 411686.9 | R15: =R16+Q15 -> 1896118.8 | S15: =R15/N15 -> 22.209649 | T15: =S15-K15 -> -0.22286842
B16: 55 | C16: 5 | D16: 560 | E16: 8 | F16: =(D16-E16)/D16 -> 0.98571429 | G16: =LT!H33 -> 77777.957 | H16: =1-LT!F33 -> 0.89645736 | I16: =1-H16 -> 0.10354264 | J16: =LT!G14 | K16: =LT!L33 -> 19.060535 | L16: =H16^F16 -> 0.89785827 | M16: =1-L16 -> 0.10214173 | N16: =N15*L15 -> 79013.615 | O16: =N16*M16 -> 8070.5874 | P16: =(((-5/24)*O15)+((2.5)*O16)+((5/24)*O17))/O16 -> 2.6296271 | Q16: =(C16*N17)+(P16*O16) -> 375937.77 | R16: =R17+Q16 -> 1484431.9 | S16: =R16/N16 -> 18.78704 | T16: =S16-K16 -> -0.27349544
B17: 60 | C17: 5 | D17: 740 | E17: 1 | F17: =(D17-E17)/D17 -> 0.99864865 | G17: =LT!H34 -> 69724.622 | H17: =1-LT!F34 -> 0.83936789 | I17: =1-H17 -> 0.16063211 | J17: =LT!G15 | K17: =LT!L34 -> 15.973311 | L17: =H17^F17 -> 0.83956653 | M17: =1-L17 -> 0.16043347 | N17: =N16*L16 -> 70943.027 | O17: =N17*M17 -> 11381.636 | P17: =(((-5/24)*O16)+((2.5)*O17)+((5/24)*O18))/O17 -> 2.5550615 | Q17: =(C17*N18)+(P17*O17) -> 326887.74 | R17: =R18+Q17 -> 1108494.2 | S17: =R17/N17 -> 15.625132 | T17: =S17-K17 -> -0.34817871
B18: 65 | C18: 5 | D18: 642 | E18: 3 | F18: =(D18-E18)/D18 -> 0.9953271 | G18: =LT!H35 -> 58524.609 | H18: =1-LT!F35 -> 0.81320919 | I18: =1-H18 -> 0.18679081 | J18: =LT!G16 | K18: =LT!L35 -> 13.551735 | L18: =H18^F18 -> 0.8139953 | M18: =1-L18 -> 0.1860047 | N18: =N17*L17 -> 59561.392 | O18: =N18*M18 -> 11078.699 | P18: =(((-5/24)*O17)+((2.5)*O18)+((5/24)*O19))/O18 -> 2.5133557 | Q18: =(C18*N19)+(P18*O18) -> 270258.17 | R18: =R19+Q18 -> 781606.43 | S18: =R18/N18 -> 13.122703 | T18: =S18-K18 -> -0.42903209
B19: 70 | C19: 5 | D19: 636 | E19: 1 | F19: =(D19-E19)/D19 -> 0.99842767 | G19: =LT!H36 -> 47592.75 | H19: =1-LT!F36 -> 0.75025524 | I19: =1-H19 -> 0.24974476 | J19: =LT!G17 | K19: =LT!L36 -> 11.090273 | L19: =H19^F19 -> 0.75059428 | M19: =1-L19 -> 0.24940572 | N19: =N18*L18 -> 48482.693 | O19: =N19*M19 -> 12091.861 | P19: =(((-5/24)*O18)+((2.5)*O19)+((5/24)*O20))/O19 -> 2.514231 | Q19: =(C19*N20)+(P19*O19) -> 212355.89 | R19: =R20+Q19 -> 511348.25 | S19: =R19/N19 -> 10.547027 | T19: =S19-K19 -> -0.54324597
B20: 75 | C20: 5 | D20: 635 | E20: 0 | F20: =(D20-E20)/D20 -> 1 | G20: =LT!H37 -> 35706.71 | H20: =1-LT!F37 -> 0.6728659 | I20: =1-H20 -> 0.3271341 | J20: =LT!G18 | K20: =LT!L37 -> 8.9498002 | L20: =H20^F20 -> 0.6728659 | M20: =1-L20 -> 0.3271341 | N20: =N19*L19 -> 36390.832 | O20: =N20*M20 -> 11904.682 | P20: =(((-5/24)*O19)+((2.5)*O20)+((5/24)*O21))/O20 -> 2.4730332 | Q20: =(C20*N21)+(P20*O20) -> 151871.42 | R20: =R21+Q20 -> 298992.36 | S20: =R20/N20 -> 8.2161453 | T20: =S20-K20 -> -0.73365493
B21: 80 | C21: 5 | D21: 578 | E21: 0 | F21: =(D21-E21)/D21 -> 1 | G21: =LT!H38 -> 24025.828 | H21: =1-LT!F38 -> 0.5691069 | I21: =1-H21 -> 0.4308931 | J21: =LT!G19 | K21: =LT!L38 -> 7.0855656 | L21: =H21^F21 -> 0.5691069 | M21: =1-L21 -> 0.4308931 | N21: =N20*L20 -> 24486.15 | O21: =N21*M21 -> 10550.913 | P21: =C21+(F21*(I21/M21)*(J21-C21)) -> 0 | Q21: =(C21*N22)+(P21*O21) -> 69676.184 | R21: =R22+Q21 -> 147120.94 | S21: =R21/N21 -> 6.0083328 | T21: =S21-K21 -> -1.0772327
B22: 85 | C22: 5 | D22: 929 | E22: 0 | F22: =(D22-E22)/D22 -> 1 | G22: =LT!H39 -> 13673.264 | H22: =1-LT!F39 -> 0 | I22: =1-H22 -> 1 | J22: =LT!G20 | K22: =LT!L39 -> 5.5574766 | L22: =H22^F22 -> 0 | M22: =1-L22 -> 1 | N22: =N21*L21 -> 13935.237 | O22: =N22*M22 -> 13935.237 | P22: =K22/F22 -> 5.5574766 | Q22: =N22/LT!E39 -> 77444.753 | R22: =Q22 -> 77444.753 | S22: =R22/N22 -> 5.5574766 | T22: =S22-K22 -> 0
B24: Mujeres, 2019
B26: Age x | C26: n | D26: nDx | E26: nDxi | I26: nqx | K26: e0 | M26: nqx_i | O26: ndx_i | Q26: L | R26: T | S26: e0_i | T26: diff | AA26: Hombres | AB26: Mujeres
B27: 0 | C27: 1 | D27: 117 | E27: 0 | F27: =(D27-E27)/D27 -> 1 | G27: =LT!H78 -> 100000 | H27: =1-LT!F78 -> 0.98991333 | I27: =1-H27 -> 0.010086673 | J27: =LT!G78 -> 0.081506787 | K27: =LT!L78 -> 74.434853 | L27: =H27^F27 -> 0.98991333 | M27: =1-L27 -> 0.010086673 | N27: 100000 | O27: =N27*M27 -> 1008.6673 | P27: =C27+(F27*(I27/M27)*(J27-C27)) -> 0.081506787 | Q27: =(C27*N28)+(P27*O27) -> 99073.546 | R27: =R28+Q27 -> 7459836.9 | S27: =R27/N27 -> 74.598369 | T27: =S27-K27 -> 0.16351564 | Z27: Sin homicidios | AA27: =S4 -> 66.858284 | AB27: =S27 -> 74.598369
B28: 1 | C28: 4 | D28: 17 | E28: 0 | F28: =(D28-E28)/D28 -> 1 | G28: =LT!H79 -> 98991.333 | H28: =1-LT!F79 -> 0.99843433 | I28: =1-H28 -> 0.0015656708 | J28: =LT!G79 -> 1.5374548 | K28: =LT!L79 -> 74.192473 | L28: =H28^F28 -> 0.99843433 | M28: =1-L28 -> 0.0015656708 | N28: =N27*L27 -> 98991.333 | O28: =N28*M28 -> 154.98784 | P28: =C28+(F28*(I28/M28)*(J28-C28)) -> 1.5374548 | Q28: =(C28*N29)+(P28*O28) -> 395583.67 | R28: =R29+Q28 -> 7360763.4 | S28: =R28/N28 -> 74.357655 | T28: =S28-K28 -> 0.16518177 | V28: Número de años que se espera que viva una mujer de 0 años hasta llegar a los 85 años. | Z28: Con homicidios | AA28: =K4 -> 66.515702 | AB28: =K27 -> 74.434853
B29: 5 | C29: 5 | D29: 6 | E29: 1 | F29: =(D29-E29)/D29 -> 0.83333333 | G29: =LT!H80 -> 98836.345 | H29: =1-LT!F80 -> 0.9994845 | I29: =1-H29 -> 0.00051549935 | J29: =LT!G80 -> 2.5 | K29: =LT!L80 -> 70.306405 | L29: =H29^F29 -> 0.9995704 | M29: =1-L29 -> 0.00042960125 | N29: =N28*L28 -> 98836.345 | O29: =N29*M29 -> 42.460217 | P29: =C29+(F29*(I29/M29)*(J29-C29)) -> 2.5001074 | Q29: =(C29*N30)+(P29*O29) -> 494075.58 | R29: =R30+Q29 -> 6965179.7 | S29: =R29/N29 -> 70.471846 | T29: =S29-K29 -> 0.1654408 | AA29: =AA27-AA28 -> 0.34258188 | AB29: =AB27-AB28 -> 0.16351564
B30: 10 | C30: 5 | D30: 15 | E30: 0 | F30: =(D30-E30)/D30 -> 1 | G30: =LT!H81 -> 98785.395 | H30: =1-LT!F81 -> 0.99872867 | I30: =1-H30 -> 0.0012713265 | J30: =LT!G81 -> 2.5 | K30: =LT!L81 -> 65.341378 | L30: =H30^F30 -> 0.99872867 | M30: =1-L30 -> 0.0012713265 | N30: =N29*L29 -> 98793.885 | O30: =N30*M30 -> 125.59928 | P30: =(((-5/24)*O29)+((2.5)*O30)+((5/24)*O31))/O30 -> 2.8268729 | Q30: =(C30*N31)+(P30*O30) -> 493696.48 | R30: =R31+Q30 -> 6471104.1 | S30: =R30/N30 -> 65.501059 | T30: =S30-K30 -> 0.15968191
B31: 15 | C31: 5 | D31: 33 | E31: 4 | F31: =(D31-E31)/D31 -> 0.87878788 | G31: =LT!H82 -> 98659.806 | H31: =1-LT!F82 -> 0.99723805 | I31: =1-H31 -> 0.0027619454 | J31: =LT!G82 -> 2.5 | K31: =LT!L82 -> 60.421371 | L31: =H31^F31 -> 0.99757243 | M31: =1-L31 -> 0.0024275709 | N31: =N30*L30 -> 98668.285 | O31: =N31*M31 -> 239.52425 | P31: =(((-5/24)*O30)+((2.5)*O31)+((5/24)*O32))/O31 -> 2.6828609 | Q31: =(C31*N32)+(P31*O31) -> 492786.42 | R31: =R32+Q31 -> 5977407.6 | S31: =R31/N31 -> 60.58084 | T31: =S31-K31 -> 0.15946908 | V31: Sin COVID | W31: Con COVID
B32: 20 | C32: 5 | D32: 45 | E32: 6 | F32: =(D32-E32)/D32 -> 0.86666667 | G32: =LT!H83 -> 98387.313 | H32: =1-LT!F83 -> 0.99606413 | I32: =1-H32 -> 0.0039358715 | J32: =LT!G83 -> 2.5 | K32: =LT!L83 -> 55.58179 | L32: =H32^F32 -> 0.99658802 | M32: =1-L32 -> 0.003411985 | N32: =N31*L31 -> 98428.761 | O32: =N32*M32 -> 335.83746 | P32: =(((-5/24)*O31)+((2.5)*O32)+((5/24)*O33))/O32 -> 2.6848187 | Q32: =(C32*N33)+(P32*O32) -> 491366.28 | R32: =R33+Q32 -> 5484621.2 | S32: =R32/N32 -> 55.721734 | T32: =S32-K32 -> 0.13994383 | V32: =([1]TV!M29-[1]TV!M47)/[1]TV!J29 -> #ERROR! | W32: =(R27-R45)/N27 -> 72.801855
B33: 25 | C33: 5 | D33: 63 | E33: 4 | F33: =(D33-E33)/D33 -> 0.93650794 | G33: =LT!H84 -> 98000.073 | H33: =1-LT!F84 -> 0.99415058 | I33: =1-H33 -> 0.0058494192 | J33: =LT!G84 -> 2.5 | K33: =LT!L84 -> 50.791539 | L33: =H33^F33 -> 0.99452095 | M33: =1-L33 -> 0.0054790469 | N33: =N32*L32 -> 98092.924 | O33: =N33*M33 -> 537.45573 | P33: =(((-5/24)*O32)+((2.5)*O33)+((5/24)*O34))/O33 -> 2.5952255 | Q33: =(C33*N34)+(P33*O33) -> 489172.16 | R33: =R34+Q33 -> 4993254.9 | S33: =R33/N33 -> 50.903314 | T33: =S33-K33 -> 0.11177589 | V33: Diff | W33: =W32-V32 -> #ERROR!
B34: 30 | C34: 5 | D34: 64 | E34: 3 | F34: =(D34-E34)/D34 -> 0.953125 | G34: =LT!H85 -> 97426.83 | H34: =1-LT!F85 -> 0.99374707 | I34: =1-H34 -> 0.0062529311 | J34: =LT!G85 -> 2.5 | K34: =LT!L85 -> 46.075678 | L34: =H34^F34 -> 0.9940393 | M34: =1-L34 -> 0.0059607003 | N34: =N33*L33 -> 97555.468 | O34: =N34*M34 -> 581.4989 | P34: =(((-5/24)*O33)+((2.5)*O34)+((5/24)*O35))/O34 -> 2.5823128 | Q34: =(C34*N35)+(P34*O34) -> 486371.46 | R34: =R35+Q34 -> 4504082.8 | S34: =R34/N34 -> 46.169455 | T34: =S34-K34 -> 0.093776863
B35: 35 | C35: 5 | D35: 82 | E35: 1 | F35: =(D35-E35)/D35 -> 0.98780488 | G35: =LT!H86 -> 96817.627 | H35: =1-LT!F86 -> 0.99199125 | I35: =1-H35 -> 0.008008751 | J35: =LT!G86 -> 2.5 | K35: =LT!L86 -> 41.349868 | L35: =H35^F35 -> 0.99208853 | M35: =1-L35 -> 0.0079114707 | N35: =N34*L34 -> 96973.969 | O35: =N35*M35 -> 767.20672 | P35: =(((-5/24)*O34)+((2.5)*O35)+((5/24)*O36))/O35 -> 2.7255577 | Q35: =(C35*N36)+(P35*O35) -> 483124.88 | R35: =R36+Q35 -> 4017711.3 | S35: =R35/N35 -> 41.430823 | T35: =S35-K35 -> 0.080954484
B36: 40 | C36: 5 | D36: 142 | E36: 2 | F36: =(D36-E36)/D36 -> 0.98591549 | G36: =LT!H87 -> 96042.238 | H36: =1-LT!F87 -> 0.98511374 | I36: =1-H36 -> 0.014886256 | J36: =LT!G87 -> 2.5 | K36: =LT!L87 -> 36.663519 | L36: =H36^F36 -> 0.98532186 | M36: =1-L36 -> 0.014678137 | N36: =N35*L35 -> 96206.762 | O36: =N36*M36 -> 1412.1361 | P36: =(((-5/24)*O35)+((2.5)*O36)+((5/24)*O37))/O36 -> 2.7125867 | Q36: =(C36*N37)+(P36*O36) -> 477803.67 | R36: =R37+Q36 -> 3534586.4 | S36: =R36/N36 -> 36.73948 | T36: =S36-K36 -> 0.075961115
B37: 45 | C37: 5 | D37: 201 | E37: 1 | F37: =(D37-E37)/D37 -> 0.99502488 | G37: =LT!H88 -> 94612.529 | H37: =1-LT!F88 -> 0.97659062 | I37: =1-H37 -> 0.023409385 | J37: =LT!G88 -> 2.5 | K37: =LT!L88 -> 32.179771 | L37: =H37^F37 -> 0.97670571 | M37: =1-L37 -> 0.023294287 | N37: =N36*L36 -> 94794.626 | O37: =N37*M37 -> 2208.1733 | P37: =(((-5/24)*O36)+((2.5)*O37)+((5/24)*O38))/O37 -> 2.6720492 | Q37: =(C37*N38)+(P37*O37) -> 468832.61 | R37: =R38+Q37 -> 3056782.8 | S37: =R37/N37 -> 32.246372 | T37: =S37-K37 -> 0.066600788
B38: 50 | C38: 5 | D38: 269 | E38: 2 | F38: =(D38-E38)/D38 -> 0.99256506 | G38: =LT!H89 -> 92397.708 | H38: =1-LT!F89 -> 0.96479472 | I38: =1-H38 -> 0.035205277 | J38: =LT!G89 -> 2.5 | K38: =LT!L89 -> 27.891211 | L38: =H38^F38 -> 0.96505184 | M38: =1-L38 -> 0.034948156 | N38: =N37*L37 -> 92586.453 | O38: =N38*M38 -> 3235.7258 | P38: =(((-5/24)*O37)+((2.5)*O38)+((5/24)*O39))/O38 -> 2.6917771 | Q38: =(C38*N39)+(P38*O38) -> 455463.49 | R38: =R39+Q38 -> 2587950.2 | S38: =R38/N38 -> 27.951715 | T38: =S38-K38 -> 0.060504482
B39: 55 | C39: 5 | D39: 352 | E39: 0 | F39: =(D39-E39)/D39 -> 1 | G39: =LT!H90 -> 89144.821 | H39: =1-LT!F90 -> 0.94195059 | I39: =1-H39 -> 0.058049408 | J39: =LT!G90 -> 2.5 | K39: =LT!L90 -> 23.817734 | L39: =H39^F39 -> 0.94195059 | M39: =1-L39 -> 0.058049408 | N39: =N38*L38 -> 89350.727 | O39: =N39*M39 -> 5186.7568 | P39: =(((-5/24)*O38)+((2.5)*O39)+((5/24)*O40))/O39 -> 2.6293215 | Q39: =(C39*N40)+(P39*O39) -> 434457.5 | R39: =R40+Q39 -> 2132486.7 | S39: =R39/N39 -> 23.866472 | T39: =S39-K39 -> 0.04873871
B40: 60 | C40: 5 | D40: 386 | E40: 0 | F40: =(D40-E40)/D40 -> 1 | G40: =LT!H91 -> 83970.017 | H40: =1-LT!F91 -> 0.92330008 | I40: =1-H40 -> 0.076699917 | J40: =LT!G91 -> 2.5 | K40: =LT!L91 -> 20.131478 | L40: =H40^F40 -> 0.92330008 | M40: =1-L40 -> 0.076699917 | N40: =N39*L39 -> 84163.97 | O40: =N40*M40 -> 6455.3695 | P40: =(((-5/24)*O39)+((2.5)*O40)+((5/24)*O41))/O40 -> 2.6356957 | Q40: =(C40*N41)+(P40*O40) -> 405557.39 | R40: =R41+Q40 -> 1698029.2 | S40: =R40/N40 -> 20.17525 | T40: =S40-K40 -> 0.043772651
B41: 65 | C41: 5 | D41: 454 | E41: 0 | F41: =(D41-E41)/D41 -> 1 | G41: =LT!H92 -> 77529.524 | H41: =1-LT!F92 -> 0.87914604 | I41: =1-H41 -> 0.12085396 | J41: =LT!G92 -> 2.5 | K41: =LT!L92 -> 16.596151 | L41: =H41^F41 -> 0.87914604 | M41: =1-L41 -> 0.12085396 | N41: =N40*L40 -> 77708.601 | O41: =N41*M41 -> 9391.3924 | P41: =(((-5/24)*O40)+((2.5)*O41)+((5/24)*O42))/O41 -> 2.6036375 | Q41: =(C41*N42)+(P41*O41) -> 366037.82 | R41: =R42+Q41 -> 1292471.8 | S41: =R41/N41 -> 16.632287 | T41: =S41-K41 -> 0.036136467
B42: 70 | C42: 5 | D42: 459 | E42: 0 | F42: =(D42-E42)/D42 -> 1 | G42: =LT!H93 -> 68159.773 | H42: =1-LT!F93 -> 0.8371243 | I42: =1-H42 -> 0.1628757 | J42: =LT!G93 -> 2.5 | K42: =LT!L93 -> 13.533913 | L42: =H42^F42 -> 0.8371243 | M42: =1-L42 -> 0.1628757 | N42: =N41*L41 -> 68317.208 | O42: =N42*M42 -> 11127.213 | P42: =(((-5/24)*O41)+((2.5)*O42)+((5/24)*O43))/O42 -> 2.5765729 | Q42: =(C42*N43)+(P42*O42) -> 314620.05 | R42: =R43+Q42 -> 926433.94 | S42: =R42/N42 -> 13.56077 | T42: =S42-K42 -> 0.026857269
B43: 75 | C43: 5 | D43: 481 | E43: 0 | F43: =(D43-E43)/D43 -> 1 | G43: =LT!H94 -> 57058.203 | H43: =1-LT!F94 -> 0.76427346 | I43: =1-H43 -> 0.23572654 | J43: =LT!G94 -> 2.5 | K43: =LT!L94 -> 10.680734 | L43: =H43^F43 -> 0.76427346 | M43: =1-L43 -> 0.23572654 | N43: =N42*L42 -> 57189.996 | O43: =N43*M43 -> 13481.2 | P43: =(((-5/24)*O42)+((2.5)*O43)+((5/24)*O44))/O43 -> 2.5728993 | Q43: =(C43*N44)+(P43*O43) -> 253229.75 | R43: =R44+Q43 -> 611813.89 | S43: =R43/N43 -> 10.697918 | T43: =S43-K43 -> 0.017184307
...

Sheet LT
A1: lt_desc | B1: year | C1: sex | D1: age | E1: mx | F1: qx | G1: ax | H1: lx | I1: dx | J1: Lx | K1: Tx | L1: ex
A21: LT VR/Census, MEX | B21: 2019 | C21: h | D21: 0 | E21: 0.011932577 | F21: 0.01180259 | G21: 0.077027036 | H21: 100000 | I21: 1180.259 | J21: 98910.653 | K21: 6651570.2 | L21: 66.515702
A22: LT VR/Census, MEX | B22: 2019 | C22: h | D22: 1 | E22: 0.00052443168 | F22: 0.0020951826 | G22: 1.6846021 | H22: 98819.741 | I22: 207.0454 | J22: 394799.57 | K22: 6552659.6 | L22: 66.309216
A23: LT VR/Census, MEX | B23: 2019 | C23: h | D23: 5 | E23: 0.00023399241 | F23: 0.0011692781 | G23: 2.5 | H23: 98612.696 | I23: 115.30566 | J23: 492775.21 | K23: 6157860 | L23: 62.444901
A24: LT VR/Census, MEX | B24: 2019 | C24: h | D24: 10 | E24: 0.00016472294 | F24: 0.00082327565 | G24: 2.5 | H24: 98497.39 | I24: 81.090503 | J24: 492284.22 | K24: 5665084.8 | L24: 57.515075
A25: LT VR/Census, MEX | B25: 2019 | C25: h | D25: 15 | E25: 0.00091136933 | F25: 0.0045464878 | G25: 2.5 | H25: 98416.299 | I25: 447.44851 | J25: 490962.88 | K25: 5172800.6 | L25: 52.560405
A26: LT VR/Census, MEX | B26: 2019 | C26: h | D26: 20 | E26: 0.0016843076 | F26: 0.0083862254 | G26: 2.5 | H26: 97968.851 | I26: 821.58887 | J26: 487790.28 | K26: 4681837.7 | L26: 47.789043
A27: LT VR/Census, MEX | B27: 2019 | C27: h | D27: 25 | E27: 0.0028527844 | F27: 0.014162913 | G27: 2.5 | H27: 97147.262 | I27: 1375.8882 | J27: 482296.59 | K27: 4194047.4 | L27: 43.17206
A28: LT VR/Census, MEX | B28: 2019 | C28: h | D28: 30 | E28: 0.0034741431 | F28: 0.017221144 | G28: 2.5 | H28: 95771.374 | I28: 1649.2926 | J28: 474733.64 | K28: 3711750.8 | L28: 38.75637
A29: LT VR/Census, MEX | B29: 2019 | C29: h | D29: 35 | E29: 0.0045432532 | F29: 0.022461149 | G29: 2.5 | H29: 94122.081 | I29: 2114.0901 | J29: 465325.18 | K29: 3237017.2 | L29: 34.391687
A30: LT VR/Census, MEX | B30: 2019 | C30: h | D30: 40 | E30: 0.0070588808 | F30: 0.034682357 | G30: 2.5 | H30: 92007.991 | I30: 3191.054 | J30: 452062.32 | K30: 2771692 | L30: 30.12447
A31: LT VR/Census, MEX | B31: 2019 | C31: h | D31: 45 | E31: 0.01083878 | F31: 0.052764152 | G31: 2.5 | H31: 88816.937 | I31: 4686.3504 | J31: 432368.81 | K31: 2319629.7 | L31: 26.116974
A32: LT VR/Census, MEX | B32: 2019 | C32: h | D32: 50 | E32: 0.015694366 | F32: 0.07550916 | G32: 2.5 | H32: 84130.587 | I32: 6352.63 | J32: 404771.36 | K32: 1887260.9 | L32: 22.432517
... A38: LT VR/Census, MEX | B38: 2019 | C38: h | D38: 80 | E38: 0.10984417 | F38: 0.4308931 | G38: 2.5 | H38: 24025.828 | I38: 10352.563 | J38: 94247.73 | K38: 170236.58 | L38: 7.0855656
A39: LT VR/Census, MEX | B39: 2019 | C39: h | D39: 85 | E39: =1/L39 -> 0.17993778 | F39: 1 | G39: NA | H39: 13673.264 | I39: 13673.264 | J39: 75988.848 | K39: 75988.848 | L39: 5.5574766
A78: LT VR/Census, MEX | B78: 2019 | C78: m | D78: 0 | E78: 0.010180995 | F78: 0.010086673 | G78: 0.081506787 | H78: 100000 | I78: 1008.6673 | J78: 99073.546 | K78: 7443485.3 | L78: 74.434853
A79: LT VR/Census, MEX | B79: 2019 | C79: m | D79: 1 | E79: 0.00039179534 | F79: 0.0015656708 | G79: 1.5374548 | H79: 98991.333 | I79: 154.98784 | J79: 395583.67 | K79: 7344411.8 | L79: 74.192473
A80: LT VR/Census, MEX | B80: 2019 | C80: m | D80: 5 | E80: 0.00010312645 | F80: 0.00051549935 | G80: 2.5 | H80: 98836.345 | I80: 50.950071 | J80: 494054.35 | K80: 6948828.1 | L80: 70.306405
A81: LT VR/Census, MEX | B81: 2019 | C81: m | D81: 10 | E81: 0.00025442703 | F81: 0.0012713265 | G81: 2.5 | H81: 98785.395 | I81: 125.58849 | J81: 493613 | K81: 6454773.8 | L81: 65.341378
A82: LT VR/Census, MEX | B82: 2019 | C82: m | D82: 15 | E82: 0.00055315297 | F82: 0.0027619454 | G82: 2.5 | H82: 98659.806 | I82: 272.493 | J82: 492617.8 | K82: 5961160.8 | L82: 60.421371
A83: LT VR/Census, MEX | B83: 2019 | C83: m | D83: 20 | E83: 0.00078872647 | F83: 0.0039358715 | G83: 2.5 | H83: 98387.313 | I83: 387.23983 | J83: 490968.47 | K83: 5468543 | L83: 55.58179
A84: LT VR/Census, MEX | B84: 2019 | C84: m | D84: 25 | E84: 0.0011733155 | F84: 0.0058494192 | G84: 2.5 | H84: 98000.073 | I84: 573.24351 | J84: 488567.26 | K84: 4977574.5 | L84: 50.791539
A85: LT VR/Census, MEX | B85: 2019 | C85: m | D85: 30 | E85: 0.0012545084 | F85: 0.0062529311 | G85: 2.5 | H85: 97426.83 | I85: 609.20325 | J85: 485611.14 | K85: 4489007.2 | L85: 46.075678
A86: LT VR/Census, MEX | B86: 2019 | C86: m | D86: 35 | E86: 0.00160819 | F86: 0.008008751 | G86: 2.5 | H86: 96817.627 | I86: 775.38827 | J86: 482149.66 | K86: 4003396.1 | L86: 41.349868
A87: LT VR/Census, MEX | B87: 2019 | C87: m | D87: 40 | E87: 0.0029995775 | F87: 0.014886256 | G87: 2.5 | H87: 96042.238 | I87: 1429.7094 | J87: 476636.92 | K87: 3521246.4 | L87: 36.663519
A88: LT VR/Census, MEX | B88: 2019 | C88: m | D88: 45 | E88: 0.0047373259 | F88: 0.023409385 | G88: 2.5 | H88: 94612.529 | I88: 2214.8211 | J88: 467525.59 | K88: 3044609.5 | L88: 32.179771
A89: LT VR/Census, MEX | B89: 2019 | C89: m | D89: 50 | E89: 0.0071672173 | F89: 0.035205277 | G89: 2.5 | H89: 92397.708 | I89: 3252.8869 | J89: 453856.32 | K89: 2577083.9 | L89: 27.891211
... A95: LT VR/Census, MEX | B95: 2019 | C95: m | D95: 80 | E95: 0.088550114 | F95: 0.36250166 | G95: 2.5 | H95: 43608.07 | I95: 15807.998 | J95: 178520.36 | K95: 357757.8 | L95: 8.2039355
A96: LT VR/Census, MEX | B96: 2019 | C96: m | D96: 85 | E96: =1/L96 -> 0.15510193 | F96: 1 | G96: NA | H96: 27800.072 | I96: 27800.072 | J96: 179237.44 | K96: 179237.44 | L96: 6.4473731

Sheet Homicidios
A1: year | B1: sex | C1: age | D1: deaths
A553: 2019 | B553: h | C553: 0 | D553: 1
A554: 2019 | B554: h | C554: 1 | D554: 0
A555: 2019 | B555: h | C555: 5 | D555: 3
A556: 2019 | B556: h | C556: 10 | D556: 0
A557: 2019 | B557: h | C557: 15 | D557: 9
A558: 2019 | B558: h | C558: 20 | D558: 25
A559: 2019 | B559: h | C559: 25 | D559: 30
A560: 2019 | B560: h | C560: 30 | D560: 20
A561: 2019 | B561: h | C561: 35 | D561: 26
A562: 2019 | B562: h | C562: 40 | D562: 14
A563: 2019 | B563: h | C563: 45 | D563: 11
A564: 2019 | B564: h | C564: 50 | D564: 7
... A1236: 2019 | B1236: m | C1236: 85 | D1236: 1

Sheet Defunciones generales
A1: year | B1: sex | C1: age | D1: deaths
A21: 2019 | B21: male | C21: 0 | D21: 143
A22: 2019 | B22: male | C22: 1 | D22: 23
A23: 2019 | B23: male | C23: 5 | D23: 14
A24: 2019 | B24: male | C24: 10 | D24: 10
A25: 2019 | B25: male | C25: 15 | D25: 56
A26: 2019 | B26: male | C26: 20 | D26: 95
A27: 2019 | B27: male | C27: 25 | D27: 144
A28: 2019 | B28: male | C28: 30 | D28: 157
A29: 2019 | B29: male | C29: 35 | D29: 197
A30: 2019 | B30: male | C30: 40 | D30: 290
A31: 2019 | B31: male | C31: 45 | D31: 398
A32: 2019 | B32: male | C32: 50 | D32: 502
... A96: 2019 | B96: m | C96: 85 | D96: 1034
